<?xml version="1.0" ?>
<!-- =================================================================================== -->
<!-- |    This document was autogenerated by xacro from lolo_auv.urdf.xacro            | -->
<!-- |    EDITING THIS FILE BY HAND IS NOT RECOMMENDED                                 | -->
<!-- =================================================================================== -->
<robot name="lolo_auv">
  <link name="lolo/base_link">
    <visual>
      <origin rpy="0 0 0" xyz="0 0 0"/>
      <geometry>
        <mesh filename="file:///home/julian/colcon_ws/install/lolo_description/share/lolo_description/mesh/lolo_hull.dae" scale="1 1 1"/>
      </geometry>
    </visual>
  </link>
  <link name="lolo/dvl_link"/>
  <link name="lolo/compass_link"/>
  <link name="lolo/fls_link"/>
  <link name="lolo/imu_link"/>
  <link name="lolo/pressure_link"/>
  <link name="lolo/gps_link"/>
  <link name="lolo/mbes_link"/>
  <link name="lolo/enu/mbes_link"/>
  <link name="lolo/usbl_link"/>
  <link name="lolo/elevator">
    <visual>
      <origin rpy="0 0 0" xyz="0 0 0"/>
      <geometry>
        <mesh filename="file:///home/julian/colcon_ws/install/lolo_description/share/lolo_description/mesh/lolo_elevator.dae" scale="1 1 1"/>
      </geometry>
    </visual>
  </link>
  <link name="lolo/rudder_stbd">
    <visual>
      <origin rpy="0 0 0" xyz="0 0 0"/>
      <geometry>
        <mesh filename="file:///home/julian/colcon_ws/install/lolo_description/share/lolo_description/mesh/lolo_rudder.dae" scale="1 1 1"/>
      </geometry>
    </visual>
  </link>
  <link name="lolo/rudder_port">
    <visual>
      <origin rpy="0 0 0" xyz="0 0 0"/>
      <geometry>
        <mesh filename="file:///home/julian/colcon_ws/install/lolo_description/share/lolo_description/mesh/lolo_rudder.dae" scale="1 1 1"/>
      </geometry>
    </visual>
  </link>
  <link name="lolo/elevon_stbd">
    <visual>
      <origin rpy="0 0 0" xyz="0 0 0"/>
      <geometry>
        <mesh filename="file:///home/julian/colcon_ws/install/lolo_description/share/lolo_description/mesh/lolo_strb_elevon.dae" scale="1 1 1"/>
      </geometry>
    </visual>
  </link>
  <link name="lolo/elevon_port">
    <visual>
      <origin rpy="0 0 0" xyz="0 0 0"/>
      <geometry>
        <mesh filename="file:///home/julian/colcon_ws/install/lolo_description/share/lolo_description/mesh/lolo_port_elevon.dae" scale="1 1 1"/>
      </geometry>
    </visual>
  </link>
  <link name="lolo/thruster_port">
    <visual>
      <origin rpy="0 0 0" xyz="0.0 0 0"/>
      <geometry>
        <mesh filename="file:///home/julian/colcon_ws/install/lolo_description/share/lolo_description/mesh/lolo_port_propeller.dae" scale="1 1 1"/>
      </geometry>
    </visual>
  </link>
  <link name="lolo/thruster_stbd">
    <visual>
      <origin rpy="0 0 0" xyz="0.0 0 0"/>
      <geometry>
        <mesh filename="file:///home/julian/colcon_ws/install/lolo_description/share/lolo_description/mesh/lolo_strb_propeller.dae" scale="1 1 1"/>
      </geometry>
    </visual>
  </link>
  <!-- Mount a 3D pose sensor -->
  <link name="lolo/pose_sensor_link">
    <visual>
      <geometry>
        <box size="0.01 0.01 0.01"/>
      </geometry>
    </visual>
  </link>
  <joint name="lolo/elevator_joint" type="revolute">
    <origin rpy="0 0 0" xyz="-0.6476 0.0 0.0135"/>
    <parent link="lolo/base_link"/>
    <child link="lolo/elevator"/>
    <limit effort="0" lower="-0.7853981633974483" upper="0.7853981633974483" velocity="0"/>
    <axis xyz="0 1 0"/>
  </joint>
  <joint name="lolo/rudder_stbd_joint" type="revolute">
    <origin rpy="0 0 0" xyz="-0.3278 -0.253 0.129"/>
    <parent link="lolo/base_link"/>
    <child link="lolo/rudder_stbd"/>
    <limit effort="0" lower="-0.7853981633974483" upper="0.7853981633974483" velocity="0"/>
    <axis xyz="0 0 1"/>
  </joint>
  <joint name="lolo/rudder_port_joint" type="revolute">
    <origin rpy="0 0 0" xyz="-0.3278 0.253 0.129"/>
    <parent link="lolo/base_link"/>
    <child link="lolo/rudder_port"/>
    <limit effort="0" lower="-0.7853981633974483" upper="0.7853981633974483" velocity="0"/>
    <axis xyz="0 0 1"/>
  </joint>
  <joint name="lolo/elevon_stbd_joint" type="revolute">
    <origin rpy="0 0 -0.19652" xyz="-0.3733 -0.4035 0.01349"/>
    <parent link="lolo/base_link"/>
    <child link="lolo/elevon_stbd"/>
    <limit effort="0" lower="-0.7853981633974483" upper="0.7853981633974483" velocity="0"/>
    <axis xyz="0 1 0"/>
  </joint>
  <joint name="lolo/elevon_port_joint" type="revolute">
    <origin rpy="0 0 0.19652" xyz="-0.3733 0.4035 0.01349"/>
    <parent link="lolo/base_link"/>
    <child link="lolo/elevon_port"/>
    <limit effort="0" lower="-0.7853981633974483" upper="0.7853981633974483" velocity="0"/>
    <axis xyz="0 1 0"/>
  </joint>
  <!-- Propeller -->
  <joint name="lolo/thruster_stbd_joint" type="continuous">
    <origin rpy="0 0 0" xyz="-0.9056 -0.2754 0.013678"/>
    <axis xyz="1 0 0"/>
    <parent link="lolo/base_link"/>
    <child link="lolo/thruster_stbd"/>
  </joint>
  <joint name="lolo/thruster_port_joint" type="continuous">
    <origin rpy="0 0 0" xyz="-0.9056 0.2754 0.013678"/>
    <axis xyz="1 0 0"/>
    <parent link="lolo/base_link"/>
    <child link="lolo/thruster_port"/>
  </joint>
  <joint name="lolo/pose_sensor_joint" type="revolute">
    <origin rpy="0 0 0" xyz="0 0 0"/>
    <parent link="lolo/base_link"/>
    <child link="lolo/pose_sensor_link"/>
    <limit effort="0" lower="0" upper="0" velocity="0"/>
  </joint>
  <joint name="lolo/dvl_joint" type="fixed">
    <origin rpy="3.14159 0 0" xyz="0.805 -0.025 -0.245"/>
    <parent link="lolo/base_link"/>
    <child link="lolo/dvl_link"/>
  </joint>
  <joint name="lolo/compass_joint" type="fixed">
    <origin rpy="0 0 0" xyz="0 0 0"/>
    <parent link="lolo/base_link"/>
    <child link="lolo/compass_link"/>
  </joint>
  <joint name="lolo/fls_joint" type="fixed">
    <origin rpy="0 0 0" xyz="0 0 0"/>
    <parent link="lolo/base_link"/>
    <child link="lolo/fls_link"/>
  </joint>
  <joint name="lolo/imu_joint" type="fixed">
    <origin rpy="3.14159 0 0" xyz="0 0 0"/>
    <parent link="lolo/base_link"/>
    <child link="lolo/imu_link"/>
  </joint>
  <joint name="lolo/pressure_joint" type="fixed">
    <origin rpy="0 0 0" xyz="0 0 0"/>
    <parent link="lolo/base_link"/>
    <child link="lolo/pressure_link"/>
  </joint>
  <joint name="lolo/gps_joint" type="fixed">
    <origin rpy="0 0 0" xyz="0.836 0 0.44"/>
    <parent link="lolo/base_link"/>
    <child link="lolo/gps_link"/>
  </joint>
  <joint name="lolo/mbes_joint" type="fixed">
    <origin rpy="0 0 0" xyz="-.751 -0.0155 0.084"/>
    <parent link="lolo/base_link"/>
    <child link="lolo/mbes_link"/>
  </joint>
  <joint name="lolo/enu/mbes_joint" type="fixed">
    <origin rpy="0 0 0" xyz="2.523 0.0155 -0.302"/>
    <parent link="lolo/base_link"/>
    <child link="lolo/enu/mbes_link"/>
  </joint>
  <joint name="lolo/usbl_joint" type="fixed">
    <origin rpy="0 0 0" xyz="0.389 0.002 0.337"/>
    <parent link="lolo/base_link"/>
    <child link="lolo/usbl_link"/>
  </joint>
</robot>
